[2019-04-30 13:04:31,107] {__init__.py:1139} INFO - Dependencies all met for <TaskInstance: Salted_Graph_Practice1.Sense_S3_Source_Data 2019-04-30T17:04:25.284426+00:00 [queued]>
[2019-04-30 13:04:31,109] {__init__.py:1139} INFO - Dependencies all met for <TaskInstance: Salted_Graph_Practice1.Sense_S3_Source_Data 2019-04-30T17:04:25.284426+00:00 [queued]>
[2019-04-30 13:04:31,109] {__init__.py:1353} INFO - 
--------------------------------------------------------------------------------
[2019-04-30 13:04:31,109] {__init__.py:1354} INFO - Starting attempt 1 of 1
[2019-04-30 13:04:31,109] {__init__.py:1355} INFO - 
--------------------------------------------------------------------------------
[2019-04-30 13:04:31,119] {__init__.py:1374} INFO - Executing <Task(S3KeySensor): Sense_S3_Source_Data> on 2019-04-30T17:04:25.284426+00:00
[2019-04-30 13:04:31,120] {base_task_runner.py:119} INFO - Running: ['airflow', 'run', 'Salted_Graph_Practice1', 'Sense_S3_Source_Data', '2019-04-30T17:04:25.284426+00:00', '--job_id', '180', '--raw', '-sd', 'DAGS_FOLDER/salted_graph.py', '--cfg_path', '/tmp/tmpzoobgiyh']
[2019-04-30 13:04:31,410] {base_task_runner.py:101} INFO - Job 180: Subtask Sense_S3_Source_Data /home/mjcarleb/anaconda3/envs/airflow4/lib/python3.7/site-packages/airflow/configuration.py:214: FutureWarning: The task_runner setting in [core] has the old default value of 'BashTaskRunner'. This value has been changed to 'StandardTaskRunner' in the running config, but please update your config before Apache Airflow 2.0.
[2019-04-30 13:04:31,411] {base_task_runner.py:101} INFO - Job 180: Subtask Sense_S3_Source_Data   FutureWarning,
[2019-04-30 13:04:31,557] {base_task_runner.py:101} INFO - Job 180: Subtask Sense_S3_Source_Data [2019-04-30 13:04:31,557] {__init__.py:51} INFO - Using executor SequentialExecutor
[2019-04-30 13:04:31,717] {base_task_runner.py:101} INFO - Job 180: Subtask Sense_S3_Source_Data [2019-04-30 13:04:31,716] {__init__.py:305} INFO - Filling up the DagBag from /home/mjcarleb/HESWork/CSCI-E29/2019sp-airflow_project-mjcarleb/dags/salted_graph.py
[2019-04-30 13:04:31,865] {base_task_runner.py:101} INFO - Job 180: Subtask Sense_S3_Source_Data [2019-04-30 13:04:31,865] {cli.py:517} INFO - Running <TaskInstance: Salted_Graph_Practice1.Sense_S3_Source_Data 2019-04-30T17:04:25.284426+00:00 [running]> on host localhost.localdomain
[2019-04-30 13:04:31,927] {s3_key_sensor.py:88} INFO - Poking for key : s3://cscie29-data/pset5/yelp_data/yeld_subset_1.csv
[2019-04-30 13:04:31,945] {logging_mixin.py:95} INFO - [2019-04-30 13:04:31,944] {credentials.py:1046} INFO - Found credentials in shared credentials file: ~/.aws/credentials
[2019-04-30 13:04:32,287] {logging_mixin.py:95} INFO - [2019-04-30 13:04:32,286] {S3_hook.py:201} INFO - Not Found
[2019-04-30 13:04:42,291] {s3_key_sensor.py:88} INFO - Poking for key : s3://cscie29-data/pset5/yelp_data/yeld_subset_1.csv
[2019-04-30 13:04:42,303] {logging_mixin.py:95} INFO - [2019-04-30 13:04:42,303] {credentials.py:1046} INFO - Found credentials in shared credentials file: ~/.aws/credentials
[2019-04-30 13:04:42,716] {logging_mixin.py:95} INFO - [2019-04-30 13:04:42,716] {S3_hook.py:201} INFO - Not Found
[2019-04-30 13:04:52,729] {s3_key_sensor.py:88} INFO - Poking for key : s3://cscie29-data/pset5/yelp_data/yeld_subset_1.csv
[2019-04-30 13:04:52,740] {logging_mixin.py:95} INFO - [2019-04-30 13:04:52,740] {credentials.py:1046} INFO - Found credentials in shared credentials file: ~/.aws/credentials
[2019-04-30 13:04:53,040] {logging_mixin.py:95} INFO - [2019-04-30 13:04:53,039] {S3_hook.py:201} INFO - Not Found
[2019-04-30 13:05:03,052] {s3_key_sensor.py:88} INFO - Poking for key : s3://cscie29-data/pset5/yelp_data/yeld_subset_1.csv
[2019-04-30 13:05:03,064] {logging_mixin.py:95} INFO - [2019-04-30 13:05:03,064] {credentials.py:1046} INFO - Found credentials in shared credentials file: ~/.aws/credentials
[2019-04-30 13:05:03,595] {logging_mixin.py:95} INFO - [2019-04-30 13:05:03,595] {S3_hook.py:201} INFO - Not Found
[2019-04-30 13:05:03,599] {__init__.py:1580} ERROR - Snap. Time is OUT.
Traceback (most recent call last):
  File "/home/mjcarleb/anaconda3/envs/airflow4/lib/python3.7/site-packages/airflow/models/__init__.py", line 1441, in _run_raw_task
    result = task_copy.execute(context=context)
  File "/home/mjcarleb/anaconda3/envs/airflow4/lib/python3.7/site-packages/airflow/sensors/base_sensor_operator.py", line 117, in execute
    raise AirflowSensorTimeout('Snap. Time is OUT.')
airflow.exceptions.AirflowSensorTimeout: Snap. Time is OUT.
[2019-04-30 13:05:03,600] {__init__.py:1611} INFO - Marking task as FAILED.
[2019-04-30 13:05:03,618] {base_task_runner.py:101} INFO - Job 180: Subtask Sense_S3_Source_Data Traceback (most recent call last):
[2019-04-30 13:05:03,619] {base_task_runner.py:101} INFO - Job 180: Subtask Sense_S3_Source_Data   File "/home/mjcarleb/anaconda3/envs/airflow4/bin/airflow", line 32, in <module>
[2019-04-30 13:05:03,619] {base_task_runner.py:101} INFO - Job 180: Subtask Sense_S3_Source_Data     args.func(args)
[2019-04-30 13:05:03,619] {base_task_runner.py:101} INFO - Job 180: Subtask Sense_S3_Source_Data   File "/home/mjcarleb/anaconda3/envs/airflow4/lib/python3.7/site-packages/airflow/utils/cli.py", line 74, in wrapper
[2019-04-30 13:05:03,619] {base_task_runner.py:101} INFO - Job 180: Subtask Sense_S3_Source_Data     return f(*args, **kwargs)
[2019-04-30 13:05:03,619] {base_task_runner.py:101} INFO - Job 180: Subtask Sense_S3_Source_Data   File "/home/mjcarleb/anaconda3/envs/airflow4/lib/python3.7/site-packages/airflow/bin/cli.py", line 523, in run
[2019-04-30 13:05:03,619] {base_task_runner.py:101} INFO - Job 180: Subtask Sense_S3_Source_Data     _run(args, dag, ti)
[2019-04-30 13:05:03,619] {base_task_runner.py:101} INFO - Job 180: Subtask Sense_S3_Source_Data   File "/home/mjcarleb/anaconda3/envs/airflow4/lib/python3.7/site-packages/airflow/bin/cli.py", line 442, in _run
[2019-04-30 13:05:03,619] {base_task_runner.py:101} INFO - Job 180: Subtask Sense_S3_Source_Data     pool=args.pool,
[2019-04-30 13:05:03,619] {base_task_runner.py:101} INFO - Job 180: Subtask Sense_S3_Source_Data   File "/home/mjcarleb/anaconda3/envs/airflow4/lib/python3.7/site-packages/airflow/utils/db.py", line 73, in wrapper
[2019-04-30 13:05:03,619] {base_task_runner.py:101} INFO - Job 180: Subtask Sense_S3_Source_Data     return func(*args, **kwargs)
[2019-04-30 13:05:03,619] {base_task_runner.py:101} INFO - Job 180: Subtask Sense_S3_Source_Data   File "/home/mjcarleb/anaconda3/envs/airflow4/lib/python3.7/site-packages/airflow/models/__init__.py", line 1441, in _run_raw_task
[2019-04-30 13:05:03,619] {base_task_runner.py:101} INFO - Job 180: Subtask Sense_S3_Source_Data     result = task_copy.execute(context=context)
[2019-04-30 13:05:03,619] {base_task_runner.py:101} INFO - Job 180: Subtask Sense_S3_Source_Data   File "/home/mjcarleb/anaconda3/envs/airflow4/lib/python3.7/site-packages/airflow/sensors/base_sensor_operator.py", line 117, in execute
[2019-04-30 13:05:03,619] {base_task_runner.py:101} INFO - Job 180: Subtask Sense_S3_Source_Data     raise AirflowSensorTimeout('Snap. Time is OUT.')
[2019-04-30 13:05:03,619] {base_task_runner.py:101} INFO - Job 180: Subtask Sense_S3_Source_Data airflow.exceptions.AirflowSensorTimeout: Snap. Time is OUT.
[2019-04-30 13:05:06,187] {logging_mixin.py:95} INFO - [2019-04-30 13:05:06,187] {jobs.py:2562} INFO - Task exited with return code 1
