[2019-05-01 18:23:06,913] {__init__.py:1139} INFO - Dependencies all met for <TaskInstance: Content_Addressable_DAG.5.Sense_S3_Source 2019-05-01T22:22:21.802856+00:00 [queued]>
[2019-05-01 18:23:06,917] {__init__.py:1139} INFO - Dependencies all met for <TaskInstance: Content_Addressable_DAG.5.Sense_S3_Source 2019-05-01T22:22:21.802856+00:00 [queued]>
[2019-05-01 18:23:06,917] {__init__.py:1353} INFO - 
--------------------------------------------------------------------------------
[2019-05-01 18:23:06,917] {__init__.py:1354} INFO - Starting attempt 1 of 1
[2019-05-01 18:23:06,917] {__init__.py:1355} INFO - 
--------------------------------------------------------------------------------
[2019-05-01 18:23:06,927] {__init__.py:1374} INFO - Executing <Task(S3KeySensor): 5.Sense_S3_Source> on 2019-05-01T22:22:21.802856+00:00
[2019-05-01 18:23:06,927] {base_task_runner.py:119} INFO - Running: ['airflow', 'run', 'Content_Addressable_DAG', '5.Sense_S3_Source', '2019-05-01T22:22:21.802856+00:00', '--job_id', '398', '--raw', '-sd', 'DAGS_FOLDER/content_addressable_dag.py', '--cfg_path', '/tmp/tmp86iv0d4y']
[2019-05-01 18:23:07,205] {base_task_runner.py:101} INFO - Job 398: Subtask 5.Sense_S3_Source /home/mjcarleb/anaconda3/envs/airflow5/lib/python3.7/site-packages/airflow/configuration.py:214: FutureWarning: The task_runner setting in [core] has the old default value of 'BashTaskRunner'. This value has been changed to 'StandardTaskRunner' in the running config, but please update your config before Apache Airflow 2.0.
[2019-05-01 18:23:07,205] {base_task_runner.py:101} INFO - Job 398: Subtask 5.Sense_S3_Source   FutureWarning,
[2019-05-01 18:23:07,372] {base_task_runner.py:101} INFO - Job 398: Subtask 5.Sense_S3_Source [2019-05-01 18:23:07,371] {__init__.py:51} INFO - Using executor SequentialExecutor
[2019-05-01 18:23:07,514] {base_task_runner.py:101} INFO - Job 398: Subtask 5.Sense_S3_Source [2019-05-01 18:23:07,514] {__init__.py:305} INFO - Filling up the DagBag from /home/mjcarleb/HESWork/CSCI-E29/2019sp-airflow_project-mjcarleb/dags/content_addressable_dag.py
[2019-05-01 18:23:07,669] {base_task_runner.py:101} INFO - Job 398: Subtask 5.Sense_S3_Source [2019-05-01 18:23:07,669] {cli.py:517} INFO - Running <TaskInstance: Content_Addressable_DAG.5.Sense_S3_Source 2019-05-01T22:22:21.802856+00:00 [running]> on host localhost.localdomain
[2019-05-01 18:23:07,733] {s3_key_sensor.py:88} INFO - Poking for key : s3://cscie29-data/pset5/yelp_data/yelp_subset_1.csv
[2019-05-01 18:23:07,751] {logging_mixin.py:95} INFO - [2019-05-01 18:23:07,751] {credentials.py:1046} INFO - Found credentials in shared credentials file: ~/.aws/credentials
[2019-05-01 18:23:08,085] {base_sensor_operator.py:124} INFO - Success criteria met. Exiting.
[2019-05-01 18:23:11,918] {logging_mixin.py:95} INFO - [2019-05-01 18:23:11,917] {jobs.py:2562} INFO - Task exited with return code 0
